/lre/home/ioulkadda/adversarial/dpo/env/lib/python3.12/site-packages/torch/cuda/__init__.py:619: UserWarning: Can't initialize NVML
  warnings.warn("Can't initialize NVML")
The following values were not passed to `accelerate launch` and had defaults used instead:
	`--num_processes` was set to a value of `1`
	`--num_machines` was set to a value of `1`
	`--mixed_precision` was set to a value of `'no'`
	`--dynamo_backend` was set to a value of `'no'`
To avoid this warning pass in values for each of the problematic parameters or run `accelerate config`.
/lre/home/ioulkadda/adversarial/dpo/env/lib/python3.12/site-packages/torch/cuda/__init__.py:619: UserWarning: Can't initialize NVML
  warnings.warn("Can't initialize NVML")
Selected Tasks: ['humaneval']
Loading model in fp32
Traceback (most recent call last):
  File "/lre/home/ioulkadda/bigcode-evaluation-harness/main.py", line 414, in <module>
    main()
  File "/lre/home/ioulkadda/bigcode-evaluation-harness/main.py", line 296, in main
    model = AutoModelForCausalLM.from_pretrained(
            ^^^^^^^^^^^^^^^^^^^^^^^^^^^^^^^^^^^^^
  File "/lre/home/ioulkadda/adversarial/dpo/env/lib/python3.12/site-packages/transformers/models/auto/auto_factory.py", line 523, in from_pretrained
    config, kwargs = AutoConfig.from_pretrained(
                     ^^^^^^^^^^^^^^^^^^^^^^^^^^^
  File "/lre/home/ioulkadda/adversarial/dpo/env/lib/python3.12/site-packages/transformers/models/auto/configuration_auto.py", line 934, in from_pretrained
    config_dict, unused_kwargs = PretrainedConfig.get_config_dict(pretrained_model_name_or_path, **kwargs)
                                 ^^^^^^^^^^^^^^^^^^^^^^^^^^^^^^^^^^^^^^^^^^^^^^^^^^^^^^^^^^^^^^^^^^^^^^^^^
  File "/lre/home/ioulkadda/adversarial/dpo/env/lib/python3.12/site-packages/transformers/configuration_utils.py", line 632, in get_config_dict
    config_dict, kwargs = cls._get_config_dict(pretrained_model_name_or_path, **kwargs)
                          ^^^^^^^^^^^^^^^^^^^^^^^^^^^^^^^^^^^^^^^^^^^^^^^^^^^^^^^^^^^^^
  File "/lre/home/ioulkadda/adversarial/dpo/env/lib/python3.12/site-packages/transformers/configuration_utils.py", line 689, in _get_config_dict
    resolved_config_file = cached_file(
                           ^^^^^^^^^^^^
  File "/lre/home/ioulkadda/adversarial/dpo/env/lib/python3.12/site-packages/transformers/utils/hub.py", line 370, in cached_file
    raise EnvironmentError(
OSError: ../adversarial/sft/models/qwen2.5-3b-instruct-sft-mistral-7b does not appear to have a file named config.json. Checkout 'https://huggingface.co/../adversarial/sft/models/qwen2.5-3b-instruct-sft-mistral-7b/tree/None' for available files.
Traceback (most recent call last):
  File "/lre/home/ioulkadda/adversarial/dpo/env/bin/accelerate", line 8, in <module>
    sys.exit(main())
             ^^^^^^
  File "/lre/home/ioulkadda/adversarial/dpo/env/lib/python3.12/site-packages/accelerate/commands/accelerate_cli.py", line 47, in main
    args.func(args)
  File "/lre/home/ioulkadda/adversarial/dpo/env/lib/python3.12/site-packages/accelerate/commands/launch.py", line 1023, in launch_command
    simple_launcher(args)
  File "/lre/home/ioulkadda/adversarial/dpo/env/lib/python3.12/site-packages/accelerate/commands/launch.py", line 643, in simple_launcher
    raise subprocess.CalledProcessError(returncode=process.returncode, cmd=cmd)
subprocess.CalledProcessError: Command '['/lre/home/ioulkadda/adversarial/dpo/env/bin/python', 'main.py', '--model', '../adversarial/sft/models/qwen2.5-3b-instruct-sft-mistral-7b', '--max_length_generation', '512', '--tasks', 'humaneval', '--temperature', '0.2', '--n_samples', '1', '--batch_size', '10', '--allow_code_execution', '--use_auth_token']' returned non-zero exit status 1.
